Workbook

Sheet Hot Dog
E2: COSTOS DE ENRROLLADO DE HOT DOG
C5: Cantidad x Kg | D5: Precio U | E5: Total | G5: Total de Empanadas producidas
B6: Harina | C6: =(G6/50) -> 0 | D6: 1.8 | E6: =(C6*D6) -> 0 | G6: =(D57) -> 0
B7: Manteca | C7: =(C6*0.4) -> 0 | D7: 4.8 | E7: =(C7*D7) -> 0
B8: Hot Dog | C8: =(C6*1) -> 0 | D8: 4 | E8: =(C8*D8) -> 0 | G8: COSTO UNITARIO x ENRROLLADO
B9: Azucar | C9: =(C6*0.25) -> 0 | D9: 1.9 | E9: =(C9*D9) -> 0 | G9: =(E14/G6) -> #DIV/0!
B10: Sal | C10: =(C6*0.02) -> 0 | D10: 0.5 | E10: =(C10*D10) -> 0
B11: Huevos x und | C11: 1 | D11: 0.3 | E11: =(C11*D11) -> 0.3
B12: Horneado | C12: 1 | D12: 2 | E12: =(C12*D12) -> 2
B13: Transporte | C13: 0 | D13: 6 | E13: =(C13*D13) -> 0
E14: =SUM(E6:E13) -> 2.3
E16: Unidades | F16: COSTO VENTA X UNIDAD | H16: UTILIDAD X UND EMPANADA
B17: Precio de venta | D17: 4.5 | E17: 12 | F17: =(D17/E17) -> 0.375 | H17: =(F17-G9) -> #DIV/0!
B18: Precio de venta | D18: 9 | E18: 12 | F18: =(D18/E18) -> 0.75 | H18: =(F18-G9) -> #DIV/0!
B19: Precio de venta | D19: 8 | E19: 14 | F19: =(D19/E19) -> 0.57142857 | H19: =(F19-G9) -> #DIV/0!
A21: Nº | B21: CLIENTES | C21: DOCENAS | D21: Cantidad x Und | E21: Precio de venta | F21: COSTO DE VENTA X UNIDAD | H21: UTILIDAD X UND EMPANADA | J21: UTILIDAD X CLIENTE
A22: 1 | B22: =Pedidos!B6 -> Pautet K1 | C22: =(Pedidos!D6) -> 0 | D22: =(C22*E17) -> 0 | E22: =(C22*D17) -> 0 | F22: =IF(D22=0,0,E22/D22) -> 0 | H22: =(F22-G9) -> #DIV/0! | J22: =(D22*H22) -> #DIV/0!
A23: 2 | B23: =Pedidos!B7 -> Alas Peruanas | C23: =(Pedidos!D7) -> 0 | D23: =(C23*12) -> 0 | E23: =(C23*D19) -> 0 | F23: =IF(D23=0,0,E23/D23) -> 0 | H23: =(F23-G9) -> #DIV/0! | J23: =(D23*H23) -> #DIV/0!
A24: 3 | B24: =Pedidos!B8 -> AP K1 | C24: =(Pedidos!D8) -> 0 | D24: =(C24*12) -> 0 | E24: =(C24*D19) -> 0 | F24: =IF(D24=0,0,E24/D24) -> 0 | H24: =(F24-G9) -> #DIV/0! | J24: =(D24*H24) -> #DIV/0!
A25: 4 | B25: =Pedidos!B9 -> AP K4 | C25: =(Pedidos!D9) -> 0 | D25: =(C25*12) -> 0 | E25: =(C25*D19) -> 0 | F25: =IF(D25=0,0,E25/D25) -> 0 | H25: =(F25-G9) -> #DIV/0! | J25: =(D25*H25) -> #DIV/0!
A26: 5 | B26: =Pedidos!B10 -> AP K6 | C26: =(Pedidos!D10) -> 0 | D26: =(C26*12) -> 0 | E26: =(C26*D19) -> 0 | F26: =IF(D26=0,0,E26/D26) -> 0 | H26: =(F26-G9) -> #DIV/0! | J26: =(D26*H26) -> #DIV/0!
A27: 6 | B27: =Pedidos!B11 -> AP K7 | C27: =(Pedidos!D11) -> 0 | D27: =(C27*12) -> 0 | E27: =(C27*D19) -> 0 | F27: =IF(D27=0,0,E27/D27) -> 0 | H27: =(F27-G9) -> #DIV/0! | J27: =(D27*H27) -> #DIV/0!
A28: 7 | B28: =Pedidos!B12 -> Sistema 2000 | C28: =(Pedidos!D12) -> 0 | D28: =(C28*12) -> 0 | E28: =(C28*D19) -> 0 | F28: =IF(D28=0,0,E28/D28) -> 0 | H28: =(F28-G9) -> #DIV/0! | J28: =(D28*H28) -> #DIV/0!
A29: 8 | B29: =Pedidos!B13 -> Corazon de Jesus | C29: =(Pedidos!D13) -> 0 | D29: =(C29*12) -> 0 | E29: =(C29*D19) -> 0 | F29: =IF(D29=0,0,E29/D29) -> 0 | H29: =(F29-G9) -> #DIV/0! | J29: =(D29*H29) -> #DIV/0!
A30: 9 | B30: =Pedidos!B14 -> Mandamiento | C30: =(Pedidos!D14) -> 0 | D30: =(C30*12) -> 0 | E30: =(C30*D19) -> 0 | F30: =IF(D30=0,0,E30/D30) -> 0 | H30: =(F30-G9) -> #DIV/0! | J30: =(D30*H30) -> #DIV/0!
A31: 10 | B31: =Pedidos!B15 -> Las Madres | C31: =(Pedidos!D15) -> 0 | D31: =(C31*12) -> 0 | E31: =(C31*D19) -> 0 | F31: =IF(D31=0,0,E31/D31) -> 0 | H31: =(F31-G9) -> #DIV/0! | J31: =(D31*H31) -> #DIV/0!
A32: 11 | B32: =Pedidos!B16 -> La Merced | C32: =(Pedidos!D16) -> 0 | D32: =(C32*E19) -> 0 | E32: =(C32*D19) -> 0 | F32: =IF(D32=0,0,E32/D32) -> 0 | H32: =(F32-G9) -> #DIV/0! | J32: =(D32*H32) -> #DIV/0!
A33: 12 | B33: =Pedidos!B17 -> SIL | C33: =(Pedidos!D17) -> 0 | D33: =(C33*12) -> 0 | E33: =(C33*D19) -> 0 | F33: =IF(D33=0,0,E33/D33) -> 0 | H33: =(F33-G9) -> #DIV/0! | J33: =(D33*H33) -> #DIV/0!
A34: 13 | B34: =Pedidos!B18 -> Columbia | C34: =(Pedidos!D18) -> 0 | D34: =(C34*12) -> 0 | E34: =(C34*D19) -> 0 | F34: =IF(D34=0,0,E34/D34) -> 0 | H34: =(F34-G9) -> #DIV/0! | J34: =(D34*H34) -> #DIV/0!
B35: =Pedidos!B19 -> Inmaculada | C35: =Pedidos!D19 -> 0 | D35: =C35*E18 -> 0 | E35: =C35*D18 -> 0 | F35: =IF(D35=0,0,E35/D35) -> 0 | H35: =(F35-G9) -> #DIV/0! | J35: =(D35*H35) -> #DIV/0!
A36: 14 | B36: =Pedidos!B20 -> Jardín 86 | C36: =(Pedidos!D20) -> 0 | D36: =(C36*12) -> 0 | E36: =(C36*D19) -> 0 | F36: =IF(D36=0,0,E36/D36) -> 0 | H36: =(F36-G9) -> #DIV/0! | J36: =(D36*H36) -> #DIV/0!
A37: 15 | B37: =Pedidos!B21 -> Agencia S/M | C37: =(Pedidos!D21) -> 0 | D37: =(C37*12) -> 0 | E37: =(C37*D19) -> 0 | F37: =IF(D37=0,0,E37/D37) -> 0 | H37: =(F37-G9) -> #DIV/0! | J37: =(D37*H37) -> #DIV/0!
A38: 16 | B38: =Pedidos!B22 -> Fátima k1 | C38: =(Pedidos!D22) -> 0 | D38: =(C38*12) -> 0 | E38: =(C38*D19) -> 0 | F38: =IF(D38=0,0,E38/D38) -> 0 | H38: =(F38-G9) -> #DIV/0! | J38: =(D38*H38) -> #DIV/0!
A39: 17 | B39: =Pedidos!B23 -> Fátima k2 | C39: =(Pedidos!D23) -> 0 | D39: =(C39*12) -> 0 | E39: =(C39*D19) -> 0 | F39: =IF(D39=0,0,E39/D39) -> 0 | H39: =(F39-G9) -> #DIV/0! | J39: =(D39*H39) -> #DIV/0!
A40: 18 | B40: =Pedidos!B24 -> Carmen Sandoval | C40: =(Pedidos!D24) -> 0 | D40: =(C40*12) -> 0 | E40: =(C40*D19) -> 0 | F40: =IF(D40=0,0,E40/D40) -> 0 | H40: =(F40-G9) -> #DIV/0! | J40: =(D40*H40) -> #DIV/0!
A41: 19 | B41: =Pedidos!B25 -> Leon | C41: =(Pedidos!D25) -> 0 | D41: =(C41*12) -> 0 | E41: =(C41*D19) -> 0 | F41: =IF(D41=0,0,E41/D41) -> 0 | H41: =(F41-G9) -> #DIV/0! | J41: =(D41*H41) -> #DIV/0!
A42: 20 | B42: =Pedidos!B26 -> B. Leguia | C42: =(Pedidos!D26) -> 0 | D42: =(C42*12) -> 0 | E42: =(C42*D19) -> 0 | F42: =IF(D42=0,0,E42/D42) -> 0 | H42: =(F42-G9) -> #DIV/0! | J42: =(D42*H42) -> #DIV/0!
A43: 21 | B43: =Pedidos!B27 -> Echenique | C43: =(Pedidos!D27) -> 0 | D43: =(C43*12) -> 0 | E43: =(C43*D19) -> 0 | F43: =IF(D43=0,0,E43/D43) -> 0 | H43: =(F43-G9) -> #DIV/0! | J43: =(D43*H43) -> #DIV/0!
A44: 22 | B44: =Pedidos!B28 -> San Martin | C44: =(Pedidos!D28) -> 0 | D44: =(C44*12) -> 0 | E44: =(C44*D20) -> 0 | F44: =IF(D44=0,0,E44/D44) -> 0 | H44: =(F44-G9) -> #DIV/0! | J44: =(D44*H44) -> #DIV/0!
A45: 23 | B45: =Pedidos!B29 -> Tras Cementerio | C45: =(Pedidos!D29) -> 0 | D45: =(C45*12) -> 0 | E45: =(C45*D19) -> 0 | F45: =IF(D45=0,0,E45/D45) -> 0 | H45: =(F45-G9) -> #DIV/0! | J45: =(D45*H45) -> #DIV/0!
...

Sheet Empa peq
E2: COSTOS DE EMPANADAS
C5: Cantidad x Kg | D5: Precio U | E5: Total | H5: PEDIDO
B6: Harina | C6: =(H7/66) -> 3.2727273 | D6: 2 | E6: =(C6*D6) -> 6.5454545 | H6: Total de Empanadas
B7: Manteca | C7: =(C6*0.4) -> 1.3090909 | D7: 6.2 | E7: =(C7*D7) -> 8.1163636 | H7: =(D63) -> 216
B8: Azucar | C8: =(C6*0.25) -> 0.81818182 | D8: 2.5 | E8: =(C8*D8) -> 2.0454545 | H8: Costo Unitario x Empanada
B9: Sal | C9: =(C6*0.035) -> 0.11454545 | D9: 0.5 | E9: =(C9*D9) -> 0.057272727 | H9: =(E18/H7) -> 0.28197391
B10: Cebolla | C10: =(C6*0.9) -> 2.9454545 | D10: 1.5 | E10: =(C10*D10) -> 4.4181818
B11: Carne | C11: =(C6*0.5) -> 1.6363636 | D11: 7 | E11: =(C11*D11) -> 11.454545
B12: Pollo | C12: =(C6*0.36) -> 1.1781818 | D12: 0 | E12: =(C12*D12) -> 0
B13: Condimentos | C13: =(C6*0.17) -> 0.55636364 | D13: 0.5 | E13: =(C13*D13) -> 0.27818182
B14: Huevos x und | C14: =(C6*0.5) -> 1.6363636 | D14: 0.3 | E14: =(C14*D14) -> 0.49090909
B15: Personal | D15: 0 | E15: 15
B16: Horneado | C16: 1 | D16: 2.5 | E16: =(C16*D16) -> 2.5
B17: Transporte | C17: 1 | D17: 7 | E17: 10
E18: =SUM(E6:E17) -> 60.906364
E21: Unidades | F21: COSTO VENTA X UNIDAD | I21: UTILIDAD X UND EMPANADA
B22: Precio de venta 22 | D22: 4.5 | E22: 12 | F22: =(D22/E22) -> 0.375 | I22: =(F22-H9) -> 0.093026094
B23: Precio de venta | D23: 5 | E23: 12 | F23: =(D23/E23) -> 0.41666667 | I23: =(F23-H9) -> 0.13469276
B24: Precio de venta | D24: 4.8 | E24: 12 | F24: =(D24/E24) -> 0.4 | I24: =(F24-H9) -> 0.11802609
B25: Precio de venta | D25: 5.5 | E25: 12 | F25: =(D25/E25) -> 0.45833333 | I25: =(F25-H9) -> 0.17635943
A27: Nª | B27: CLIENTES | C27: DOCENAS | D27: Cantidad x Und | E27: Precio de venta | F27: COSTO DE VENTA X UNIDAD | H27: UTILIDAD X UND EMPANADA | J27: UTILIDAD X CLIENTE
A28: 1 | B28: =Pedidos!B6 -> Pautet K1 | C28: =(Pedidos!C6) -> 1 | D28: =(C28*12) -> 12 | E28: =(C28*D22) -> 4.5 | F28: =IF(D28=0,0,E28/D28) -> 0.375 | H28: =(F28-H9) -> 0.093026094 | J28: =(D28*H28) -> 1.1163131
A29: 2 | B29: =Pedidos!B7 -> Alas Peruanas | C29: =(Pedidos!C7) -> 2 | D29: =(C29*12) -> 24 | E29: =(C29*D25) -> 11 | F29: =IF(D29=0,0,E29/D29) -> 0.45833333 | H29: =(F29-H9) -> 0.17635943 | J29: =(D29*H29) -> 4.2326263
A30: 3 | B30: =Pedidos!B8 -> AP K1 | C30: =(Pedidos!C8) -> 4 | D30: =(C30*12) -> 48 | E30: =(C30*D23) -> 20 | F30: =IF(D30=0,0,E30/D30) -> 0.41666667 | H30: =(F30-H9) -> 0.13469276 | J30: =(D30*H30) -> 6.4652525
A31: 4 | B31: AP K4 | C31: =(Pedidos!C9) -> 2 | D31: =(C31*12) -> 24 | E31: =(C31*D23) -> 10 | F31: =IF(D31=0,0,E31/D31) -> 0.41666667 | H31: =(F31-H9) -> 0.13469276 | J31: =(D31*H31) -> 3.2326263
A32: 5 | B32: =Pedidos!B9 -> AP K4 | C32: =(Pedidos!C10) -> 0 | D32: =(C32*12) -> 0 | E32: =(C32*D25) -> 0 | F32: =IF(D32=0,0,E32/D32) -> 0 | H32: =(F32-H9) -> -0.28197391 | J32: =(D32*H32) -> 0
A33: 6 | B33: =Pedidos!B11 -> AP K7 | C33: =(Pedidos!C11) -> 2 | D33: =(C33*12) -> 24 | E33: =(C33*D25) -> 11 | F33: =IF(D33=0,0,E33/D33) -> 0.45833333 | H33: =(F33-H9) -> 0.17635943 | J33: =(D33*H33) -> 4.2326263
A34: 7 | B34: =Pedidos!B12 -> Sistema 2000 | C34: =(Pedidos!C12) -> 3 | D34: =(C34*12) -> 36 | E34: =(C34*D23) -> 15 | F34: =IF(D34=0,0,E34/D34) -> 0.41666667 | H34: =(F34-H9) -> 0.13469276 | J34: =(D34*H34) -> 4.8489394
A35: 8 | B35: =Pedidos!B13 -> Corazon de Jesus | C35: =(Pedidos!C13) -> 2 | D35: =(C35*12) -> 24 | E35: =(C35*D23) -> 10 | F35: =IF(D35=0,0,E35/D35) -> 0.41666667 | H35: =(F35-H9) -> 0.13469276 | J35: =(D35*H35) -> 3.2326263
A36: 9 | B36: =Pedidos!B14 -> Mandamiento | C36: =(Pedidos!C14) -> 2 | D36: =(C36*12) -> 24 | E36: =(C36*D23) -> 10 | F36: =IF(D36=0,0,E36/D36) -> 0.41666667 | H36: =(F36-H9) -> 0.13469276 | J36: =(D36*H36) -> 3.2326263
A37: 10 | B37: =Pedidos!B15 -> Las Madres | C37: =(Pedidos!C15) -> 0 | D37: =(C37*12) -> 0 | E37: =(C37*D24) -> 0 | F37: =IF(D37=0,0,E37/D37) -> 0 | H37: =(F37-H9) -> -0.28197391 | J37: =(D37*H37) -> 0
A38: 11 | B38: =Pedidos!B16 -> La Merced | C38: =(Pedidos!C16) -> 0 | D38: =(C38*12) -> 0 | E38: =(C38*D24) -> 0 | F38: =IF(D38=0,0,E38/D38) -> 0 | H38: =(F38-H9) -> -0.28197391 | J38: =(D38*H38) -> 0
A39: 12 | B39: =Pedidos!B17 -> SIL | C39: =(Pedidos!C17) -> 0 | D39: =(C39*12) -> 0 | E39: =(C39*D23) -> 0 | F39: =IF(D39=0,0,E39/D39) -> 0 | H39: =(F39-H9) -> -0.28197391 | J39: =(D39*H39) -> 0
A40: 13 | B40: =Pedidos!B18 -> Columbia | C40: =(Pedidos!C18) -> 0 | D40: =(C40*12) -> 0 | E40: =(C40*D23) -> 0 | F40: =IF(D40=0,0,E40/D40) -> 0 | H40: =(F40-H9) -> -0.28197391 | J40: =(D40*H40) -> 0
B41: =Pedidos!B19 -> Inmaculada | C41: =Pedidos!C19 -> 0 | D41: =(C41*12) -> 0 | E41: =(C41*D23) -> 0 | F41: =IF(D41=0,0,E41/D41) -> 0 | H41: =(F41-H9) -> -0.28197391 | J41: =(D41*H41) -> 0
A42: 14 | B42: =Pedidos!B20 -> Jardín 86 | C42: =(Pedidos!C20) -> 0 | D42: =(C42*12) -> 0 | E42: =(C42*D23) -> 0 | F42: =IF(D42=0,0,E42/D42) -> 0 | H42: =(F42-H9) -> -0.28197391 | J42: =(D42*H42) -> 0
A43: 15 | B43: =Pedidos!B21 -> Agencia S/M | C43: =(Pedidos!C21) -> 0 | D43: =(C43*12) -> 0 | E43: =(C43*D22) -> 0 | F43: =IF(D43=0,0,E43/D43) -> 0 | H43: =(F43-H9) -> -0.28197391 | J43: =(D43*H43) -> 0
A44: 16 | B44: =Pedidos!B22 -> Fátima k1 | C44: =(Pedidos!C22) -> 0 | D44: =(C44*12) -> 0 | E44: =(C44*D23) -> 0 | F44: =IF(D44=0,0,E44/D44) -> 0 | H44: =(F44-H9) -> -0.28197391 | J44: =(D44*H44) -> 0
A45: 17 | B45: =Pedidos!B23 -> Fátima k2 | C45: =(Pedidos!C23) -> 0 | D45: =(C45*12) -> 0 | E45: =(C45*D23) -> 0 | F45: =IF(D45=0,0,E45/D45) -> 0 | H45: =(F45-H9) -> -0.28197391 | J45: =(D45*H45) -> 0
A46: 18 | B46: =Pedidos!B24 -> Carmen Sandoval | C46: =(Pedidos!C24) -> 0 | D46: =(C46*12) -> 0 | E46: =(C46*D23) -> 0 | F46: =IF(D46=0,0,E46/D46) -> 0 | H46: =(F46-H9) -> -0.28197391 | J46: =(D46*H46) -> 0
...

Sheet Empa gran
E2: COSTOS DE EMPANADAS
C5: Cantidad x Kg | D5: Precio U | E5: Total | H5: PEDIDO
B6: Harina | C6: =(H7/40) -> 0 | D6: =('Empa peq'!D6) -> 2 | E6: =(C6*D6) -> 0 | H6: Total de Empanadas
B7: Manteca | C7: =(C6*0.4) -> 0 | D7: =('Empa peq'!D7) -> 6.2 | E7: =(C7*D7) -> 0 | H7: =(D31) -> 0
B8: Azucar | C8: =(C6*0.25) -> 0 | D8: =('Empa peq'!D8) -> 2.5 | E8: =(C8*D8) -> 0 | H8: Costo Unitario x Empanada
B9: Sal | C9: =(C6*0.02) -> 0 | D9: =('Empa peq'!D9) -> 0.5 | E9: =(C9*D9) -> 0 | H9: =(E18/H7) -> #DIV/0!
B10: Cebolla | C10: =(C6*0.75) -> 0 | D10: =('Empa peq'!D10) -> 1.5 | E10: =(C10*D10) -> 0
B11: Carne | C11: =C6*0.5 -> 0 | D11: =('Empa peq'!D11) -> 7 | E11: =(C11*D11) -> 0
B12: Pollo | C12: =(C6*0.5) -> 0 | D12: =('Empa peq'!D12) -> 0 | E12: =(C12*D12) -> 0
B13: Condimentos | C13: =(C6*0.5) -> 0 | D13: =('Empa peq'!D13) -> 0.5 | E13: =(C13*D13) -> 0
B14: Huevos x und | C14: 1 | D14: =('Empa peq'!D14) -> 0.3 | E14: =(C14*D14) -> 0.3
B15: Personal | D15: =('Empa peq'!D15) -> 0
B16: Horneado | C16: 1 | D16: =('Empa peq'!D16) -> 2.5 | E16: =(C16*D16) -> 2.5
B17: Transporte | C17: 1 | D17: =('Empa peq'!D17) -> 7
E18: =SUM(E6:E17) -> 2.8
E21: Unidades | F21: COSTO VENTA X UNIDAD | I21: UTILIDAD X UND EMPANADA
B22: Precio de venta | D22: 8 | E22: 14
B23: Precio de venta | D23: 9 | E23: 12 | F23: =(D23/E23) -> 0.75 | I23: =(F23-H9) -> #DIV/0!
A25: Nª | B25: CLIENTES | C25: DOCENAS | D25: Cantidad x Und | E25: Precio de venta | F25: COSTO DE VENTA X UNIDAD | H25: UTILIDAD X UND EMPANADA | J25: UTILIDAD X CLIENTE
A26: 1 | B26: Las Madres | C26: =(Pedidos!E15) -> 0 | D26: =C26*E23 -> 0 | E26: =C26*D23 -> 0 | F26: =IF(D26=0,0,E26/D26) -> 0 | H26: =(F26-H9) -> #DIV/0! | J26: =(D26*H26) -> #DIV/0!
A27: 2 | B27: La Merced | C27: =(Pedidos!E16) -> 0 | D27: =C27*E22 -> 0 | E27: =C27*D22 -> 0 | F27: =IF(D27=0,0,E27/D27) -> 0 | H27: =(F27-H9) -> #DIV/0! | J27: =(D27*H27) -> #DIV/0!
A28: 3 | B28: Sil | C28: =(Pedidos!E17) -> 0 | D28: =C28*E23 -> 0 | E28: =C28*D23 -> 0 | F28: =IF(D28=0,0,E28/D28) -> 0 | H28: =(F28-H9) -> #DIV/0! | J28: =(D28*H28) -> #DIV/0!
B29: Columbia | C29: =(Pedidos!E18) -> 0 | D29: =C29*E23 -> 0 | E29: =C29*D23 -> 0 | F29: =IF(D29=0,0,E29/D29) -> 0 | H29: =(F29-H9) -> #DIV/0! | J29: =(D29*H29) -> #DIV/0!
B30: Inmaculada | C30: =Pedidos!E19 -> 0 | D30: =C30*E23 -> 0 | E30: =C30*D23 -> 0 | F30: =IF(D30=0,0,E30/D30) -> 0 | H30: =(F30-H9) -> #DIV/0! | J30: =(D30*H30) -> #DIV/0!
D31: =SUM(D26:D30) -> 0 | J31: =SUM(J26:J29) -> #DIV/0!
B33: Numero de latas | C33: =D31/24 -> 0

Sheet Pedidos
E3: x unidad
C4: EMPANADAS PEQUEÑAS | E4: EMPANADAS GRANDES
A5: Nª | B5: CLIENTES | D5: HOT DOG | F5: COBRAR
A6: 1 | B6: Pautet K1 | C6: 1 | E6: 0 | F6: =('Empa peq'!E28+'Hot Dog'!E22) -> 4.5
A7: 2 | B7: Alas Peruanas | C7: 2 | D7: 0 | E7: 0 | F7: =('Empa peq'!E29+'Hot Dog'!E23) -> 11
A8: 3 | B8: AP K1 | C8: 4 | D8: 0 | E8: 0 | F8: =('Empa peq'!E30+'Hot Dog'!E24) -> 20
A9: 4 | B9: AP K4 | C9: 2 | D9: 0 | E9: 0 | F9: =('Empa peq'!E31+'Hot Dog'!E25) -> 10
A10: 5 | B10: AP K6 | F10: =('Empa peq'!E32+'Hot Dog'!E26) -> 0
A11: 6 | B11: AP K7 | C11: 2 | F11: =('Empa peq'!E33+'Hot Dog'!E27) -> 11
A12: 7 | B12: Sistema 2000 | C12: 3 | F12: =('Empa peq'!E34+'Hot Dog'!E28) -> 15
A13: 8 | B13: Corazon de Jesus | C13: 2 | F13: =('Empa peq'!E35+'Hot Dog'!E29) -> 10
A14: 9 | B14: Mandamiento | C14: 2 | F14: =('Empa peq'!E36+'Hot Dog'!E30) -> 10
A15: 10 | B15: Las Madres | F15: =('Empa peq'!E37+'Hot Dog'!E31+'Empa gran'!E26) -> 0
A16: 11 | B16: La Merced | F16: =('Empa peq'!E38+'Hot Dog'!E32+'Empa gran'!E27) -> 0
A17: 12 | B17: SIL | F17: =('Empa peq'!E39+'Hot Dog'!E33+'Empa gran'!E28) -> 0
A18: 13 | B18: Columbia | F18: =('Empa peq'!E40+'Hot Dog'!E34+'Empa gran'!E29) -> 0
B19: Inmaculada | F19: ='Hot Dog'!E35+'Empa peq'!E41+'Empa gran'!E30 -> 0
A20: 14 | B20: Jardín 86 | F20: =('Empa peq'!E42+'Hot Dog'!E36) -> 0
A21: 15 | B21: Agencia S/M | F21: =('Empa peq'!E43+'Hot Dog'!E37) -> 0
A22: 16 | B22: Fátima k1 | F22: =('Empa peq'!E44+'Hot Dog'!E38) -> 0
A23: 17 | B23: Fátima k2 | F23: =('Empa peq'!E45+'Hot Dog'!E39) -> 0
A24: 18 | B24: Carmen Sandoval | F24: =('Empa peq'!E46+'Hot Dog'!E40) -> 0
A25: 19 | B25: Leon | F25: =('Empa peq'!E47+'Hot Dog'!E41) -> 0
A26: 20 | B26: B. Leguia | F26: =('Empa peq'!E48+'Hot Dog'!E42) -> 0
A27: 21 | B27: Echenique | F27: =('Empa peq'!E49+'Hot Dog'!E43) -> 0
A28: 22 | B28: San Martin | F28: =('Empa peq'!E50+'Hot Dog'!E44) -> 0
A29: 23 | B29: Tras Cementerio | F29: =('Empa peq'!E51+'Hot Dog'!E45) -> 0
A30: 24 | B30: Kuri | F30: =('Empa peq'!E52+'Hot Dog'!E46) -> 0
A31: 25 | B31: Ugel | F31: =('Empa peq'!E53+'Hot Dog'!E47) -> 0
C32: 0 | D32: 0 | F32: =('Empa peq'!E54+'Hot Dog'!E48) -> 0
C33: 0 | D33: 0 | F33: =('Empa peq'!E55+'Hot Dog'!E49) -> 0
C34: 0 | D34: 0 | F34: =('Empa peq'!E56+'Hot Dog'!E50) -> 0
C35: 0 | D35: 0 | F35: =('Empa peq'!E57+'Hot Dog'!E51) -> 0
C36: 0 | D36: 0 | F36: =('Empa peq'!E58+'Hot Dog'!E52) -> 0
C37: 0 | D37: 0 | F37: =('Empa peq'!E59+'Hot Dog'!E53) -> 0
B38: Otros | C38: 0 | D38: 0 | F38: =('Empa peq'!E60+'Hot Dog'!E54) -> 0
C39: 0 | D39: 0
C40: =SUM(C6:C39) -> 18 | D40: =SUM(D6:D39) -> 0 | E40: =SUM(E6:E39) -> 0 | F40: =SUM(F6:F39) -> 91.5

Sheet Compras
D3: CANTIDAD TOTAL | E3: PRECIO TOTAL
C5: Harina | D5: ='Hot Dog'!C6+'Empa peq'!C6+'Empa gran'!C6 -> 3.2727273 | E5: =D5*'Empa peq'!D6 -> 6.5454545
C6: Manteca | D6: ='Hot Dog'!C7+'Empa peq'!C7+'Empa gran'!C7 -> 1.3090909 | E6: =D6*'Empa peq'!D7 -> 8.1163636
C7: Azucar | D7: ='Hot Dog'!C9+'Empa peq'!C8+'Empa gran'!C8 -> 0.81818182 | E7: =D7*'Empa peq'!D8 -> 2.0454545
C8: Cebolla | D8: ='Empa peq'!C10+'Empa gran'!C10 -> 2.9454545 | E8: =D8*'Empa peq'!D10 -> 4.4181818
C9: Carne | D9: ='Empa peq'!C11+'Empa gran'!C11 -> 1.6363636 | E9: =D9*'Empa peq'!D11 -> 11.454545
E10: =SUM(E5:E9) -> 32.58
